Workbook

Sheet (1) البيانات الاساسية
A1: بيانات معد التقرير
A2: الاسم | B2: الأستاذ مهدي بوخمسين | C2: تاريخ التقرير | D2: 46215
A3: رقم الجوال | B3: 596988800 | C3: تقرير الربع | D3: Q2
A4: البريد الإلكتروني | B4: mahdi@etqan-cpa.sa
A6: البيانات الأساسية للمشروع
A7: رقم ترخيص المشروع | B7: أ/208 | C7: سعر الارض | D7: 82894783
A8: اسم المشروع | B8: ايال الاصالة | C8: إجمالي قيمة وحدات المشروع | D8: =D35 -> 3.1610032e+08
A9: اسم المطور | B9: شركة محمد الحبيب العقارية | C9: اجمالي التكاليف الانشائية التقديرية | D9: 181157708
A10: اسم مكتب المحاسب القانوني | B10: شركة إتقان للاستشارات المهنية | C10: إجمالي التكاليف الإدارية التسويقية التقديرية | D10: 40849315
A11: آمين الحساب (البنك) | B11: بنك الرياض | C11: اجمالي التكاليف التقديرية | D11: =D9+D10 -> 222007023
A12: رقم حساب الضمان (ايبان) | B12: 2189923619940 | C12: نسبة هامش الربح المتوقع | D12: =(D8-(D9+D10+D7))/D8 -> 0.035427079
A13: اسم المقاول | B13: شركة مجرة البناء للمقاولات | C13: قيمة عقد المقاول | D13: 2.2979733e+08
A14: اسم المقاول 2 | C14: قيمة عقد المقاول 2
A15: اسم المقاول 3 | C15: قيمة عقد المقاول 3
A16: اسم المقاول 4 | C16: قيمة عقد المقاول 4
A18: وحدات المشروع
A19: نوع الوحدات | C19: العدد | D19: اجمالي قيمة الوحدات
A20: شقق
A21: فلل | C21: 455 | D21: 3.1610032e+08
A22: دوبلكس
A23: أراضي سكنية
A24: أراضي تجارية
A25: أراضي صناعية
A26: أراضي زراعية
A27: أراضي سياحية
A28: أدوار
A29: مكاتب تجارية
A30: تاون هاوس
A31: مكاتب تجارية
A32: غرف فندقية
A33: أجنحة فندقية
A34: بنت هاوس
A35: الإجمالي | C35: =SUM(C20:C34) -> 455 | D35: =SUM(D20:D34) -> 3.1610032e+08

Sheet (2) وثائق الصرف
A1: وثائق الصرف
A2: # | B2: نوع حساب الضمان | C2: البند | D2: رقم وثيقة الصرف | E2: تاريخ الوثيقة | F2: اسم المستفيد | G2: صفة المستفيد | H2: بيان الصرف | I2: حالة الوثيقة | J2: تاريخ اعتماد الوثيقة | K2: تاريخ الدفع | L2: المبلغ
A3: 1 | B3: حساب الانشاءات | C3: انشائي | D3: ST001 | E3: 45649 | F3: شركة مجرة البناء للمقاولات | G3: مقاول | H3: مستخلص أعمال رقم 1 | I3: مستحق | J3: 45649 | K3: 45649 | L3: 16198413
A4: 2 | B4: حساب الانشاءات | C4: انشائي | D4: ST002 | E4: 45672 | F4: شركة مجرة البناء للمقاولات | G4: مقاول | H4: مستخلص أعمال رقم 2 | I4: مستحق | J4: 45672 | K4: 45672 | L4: 8410582.1
A5: 3 | B5: حساب الانشاءات | C5: انشائي | D5: ST003 | E5: 45718 | F5: شركة مجرة البناء للمقاولات | G5: مقاول | H5: مستخلص أعمال رقم 3 | I5: مستحق | J5: 45718 | K5: 45749 | L5: 11893161
A6: 4 | B6: حساب الانشاءات | C6: انشائي | D6: ST004 | E6: 45780 | F6: شركة مجرة البناء للمقاولات | G6: مقاول | H6: مستخلص أعمال رقم 4 | I6: مستحق | J6: 45780 | K6: 45780 | L6: 6000000
A7: 5 | B7: حساب الانشاءات | C7: انشائي | D7: ST0005 | E7: 45763 | F7: شركة مجرة البناء للمقاولات | G7: مقاول | H7: مستخلص أعمال رقم 4 | I7: مستحق | J7: 45763 | K7: 45764 | L7: 828427.53
A8: 6 | B8: حساب الانشاءات | C8: انشائي | D8: ST0006 | E8: 45763 | F8: شركة مجرة البناء للمقاولات | G8: مقاول | H8: مستخلص أعمال رقم 5 | I8: مستحق | J8: 45763 | K8: 45764 | L8: 1475000
A9: 7 | B9: حساب الانشاءات | C9: انشائي | D9: ST0008 | E9: 45790 | F9: شركة مجرة البناء للمقاولات | G9: مقاول | H9: مستخلص أعمال رقم 5 | I9: مستحق | J9: 45790 | K9: 45790 | L9: 4096809.7
A10: 8 | B10: حساب الانشاءات | C10: انشائي | D10: ST0007 | E10: 45790 | F10: شركة مجرة البناء للمقاولات | G10: مقاول | H10: مستخلص أعمال رقم 5 | I10: مستحق | J10: 45790 | K10: 45722 | L10: 7150000
A11: 9 | B11: حساب الانشاءات | C11: انشائي | D11: ST0009 | E11: 45790 | F11: شركة مجرة البناء للمقاولات | G11: مقاول | H11: مستخلص أعمال رقم 6 | I11: مستحق | J11: 45790 | K11: 45826 | L11: 12073551
A12: 10 | B12: حساب الانشاءات | C12: انشائي | D12: ST0010 | E12: 45722 | F12: شركة مجرة البناء للمقاولات | G12: مقاول | H12: مستخلص أعمال رقم 7 | I12: مستحق | J12: 45722 | K12: 45832 | L12: 13600000
A13: 11 | B13: حساب الانشاءات | C13: انشائي | D13: SAT0012 | E13: 45858 | F13: شركة مجرة البناء للمقاولات | G13: مقاول | H13: مستخلص أعمال رقم 8 | I13: مستحق | J13: 45858 | K13: 45858 | L13: 6880131.9
A14: 12 | B14: حساب الانشاءات | C14: انشائي | D14: SAT0013 | E14: 45858 | F14: الشركة الوطنية للاسكان | G14: مقاول | H14: فاتورة تطوير ارض | I14: مستحق | J14: 45858 | K14: 45858 | L14: 11248208
... A41: 39 | B41: حساب الإداري والتسويقي | C41: اداري | D41: MAN001 | E41: 45608 | F41: شركة محمد عبد العزيز الحبيب وشركاه للاستثمار العقاري | G41: أخرى (يتم ذكر صفة المستفيد في بيان الصرف) | H41: فواتير الاستشاري الهندسي والمراقب المالي | I41: مستحق | J41: 45608 | K41: 45608 | L41: 202456.35
A42: 40 | B42: حساب الإداري والتسويقي | C42: اداري | D42: MAN004 | E42: 23/12/2024 | F42: شركة نبيل عباس للاستشارات الهندسية | G42: الاستشاري الهندسي | H42: رواتب الكادر الهندسي عن نوفمبر 2024 | I42: مستحق | J42: 23/12/2024 | K42: 23/12/2024 | L42: 109787.05
A43: 41 | B43: حساب الإداري والتسويقي | C43: اداري | D43: MAN003 | E43: 23/12/2024 | F43: الشركة الوطنية للإسكان | G43: أخرى (يتم ذكر صفة المستفيد في بيان الصرف) | H43: خدمات تطوير فبراير ومارس | I43: مستحق | J43: 23/12/2024 | K43: 23/12/2024 | L43: 1351829.4
A44: 42 | B44: حساب الإداري والتسويقي | C44: تسويقي | D44: MAN002 | E44: 23/12/2024 | F44: شركة إتقان المكان المحدودة | G44: مسوق | H44: عمولة المسوق العقاري عن تسويق وبيع وحدات المشروع | I44: مستحق | J44: 23/12/2024 | K44: 23/12/2024 | L44: 3798594.3
A45: 43 | B45: حساب الإداري والتسويقي | C45: اداري | D45: MAN005 | E45: 23/12/2024 | F45: شركة نبيل عباس للاستشارات الهندسية | G45: الاستشاري الهندسي | H45: رواتب الكادر الهندسي عن ديسمبر 2024 | I45: مستحق | J45: 23/12/2024 | K45: 23/12/2024 | L45: 119600
A46: 44 | B46: حساب الإداري والتسويقي | C46: اداري | D46: MAN006 | E46: 45992 | F46: شركة اتقان للاستشارات المهنية | G46: المحاسب القانوني | H46: اتعاب المراقب المالي لشهر ديسمبر 2024 | I46: مستحق | J46: 45992 | K46: 45992 | L46: 11500
A47: 45 | B47: حساب الإداري والتسويقي | C47: اداري | D47: MAN007 | E47: 15/1/2025 | F47: الشركة الوطنية للإسكان | G47: أخرى (يتم ذكر صفة المستفيد في بيان الصرف) | H47: عمولة 3% خدمات التطوير من شهر ابريل - ديسمبر 2024 | I47: مستحق | J47: 15/1/2025 | K47: 15/1/2025 | L47: 2650297
A48: 46 | B48: حساب الإداري والتسويقي | C48: اداري | D48: MAN009 | E48: 45718 | F48: شركة نبيل عباس للاستشارات الهندسية | G48: الاستشاري الهندسي | H48: اتعاب الاستشاري الهندسي عن شهر يناير 2025 | I48: مستحق | J48: 45718 | K48: 45749 | L48: 127288.3
A49: 47 | B49: حساب الإداري والتسويقي | C49: تسويقي | D49: MAN008 | E49: 45718 | F49: شركة إتقان المكان المحدودة | G49: مسوق | H49: جزء من اتعاب فاتوة تسويق ديسمبر 2024 | I49: مستحق | J49: 45718 | K49: 45749 | L49: 1500000
A50: 48 | B50: حساب الإداري والتسويقي | C50: اداري | D50: MAN010 | E50: 19/2/2025 | F50: الشركة الوطنية للإسكان | G50: أخرى (يتم ذكر صفة المستفيد في بيان الصرف) | H50: عمولة 3% خدمات التطوير يناير 2025 | I50: مستحق | J50: 19/2/2025 | K50: 19/2/2025 | L50: 266808.43
A51: 49 | B51: حساب الإداري والتسويقي | C51: اداري | D51: MAN013 | E51: 45780 | F51: شركة نبيل عباس للاستشارات الهندسية | G51: الاستشاري الهندسي | H51: اتعاب الاستشاري الهندسي عن شهر فبراير 2025 | I51: مستحق | J51: 45780 | K51: 45780 | L51: 167219.58
A52: 50 | B52: حساب الإداري والتسويقي | C52: تسويقي | D52: MAN012 | E52: 24/3/2025 | F52: شركة إتقان المكان المحدودة | G52: مسوق | H52: جزء من اتعاب فاتوة تسويق ديسمبر 2024 | I52: مستحق | J52: 24/3/2025 | K52: 24/3/2025 | L52: 1100000
A53: 51 | B53: حساب الإداري والتسويقي | C53: اداري | D53: MAN00018 | E53: 14/5/2025 | F53: شركة نبيل عباس للاستشارات الهندسية | G53: الاستشاري الهندسي | H53: رواتب الكادر الهندسي لشهر أبريل 2025 | I53: مستحق | J53: 14/5/2025 | K53: 45753 | L53: 169912.5
A54: 52 | B54: حساب الإداري والتسويقي | C54: اداري | D54: MAN00011 | E54: 16/4/2025 | F54: شركة اتقان للاستشارات المهنية | G54: المحاسب القانوني | H54: فاتورة أتعاب الإشراف المحاسبي شهر 1 و2 و3 2025 | I54: مستحق | J54: 16/4/2025 | K54: 17/4/2025 | L54: 34500
A55: 53 | B55: حساب الإداري والتسويقي | C55: اداري | D55: MAN00014A | E55: 16/5/2025 | F55: شركة محمد عبد العزيز الحبيب وشركاه للاستثمار العقاري | G55: أخرى (يتم ذكر صفة المستفيد في بيان الصرف) | H55: رسوم الأشراف والمتابعة للنصف الثاني عام 2024 | I55: مستحق | J55: 16/5/2025 | K55: 17/4/2025 | L55: 75959.28
A56: 54 | B56: حساب الإداري والتسويقي | C56: اداري | D56: MAN00015 | E56: 45813 | F56: شركة محمد عبد العزيز الحبيب وشركاه للاستثمار العقاري | G56: أخرى (يتم ذكر صفة المستفيد في بيان الصرف) | H56: رسوم الأشراف والمتابعة للنصف الأول عام 2024 | I56: مستحق | J56: 45813 | K56: 45813 | L56: 16842.46
A57: 55 | B57: حساب الإداري والتسويقي | C57: اداري | D57: MAN00016 | E57: 45813 | F57: شركة نبيل عباس للاستشارات الهندسية | G57: الاستشاري الهندسي | H57: الدفعة الأولى من قيمة العقد بعد انجاز 25% | I57: مستحق | J57: 45813 | K57: 45813 | L57: 276000
A58: 56 | B58: حساب الإداري والتسويقي | C58: اداري | D58: MAN00014 | E58: 45753 | F58: شركة نبيل عباس للاستشارات الهندسية | G58: الاستشاري الهندسي | H58: رواتب الكادر الهندسي لشهر مارس 2025 | I58: مستحق | J58: 45753 | K58: 14/5/2025 | L58: 169912.5
A59: 57 | B59: حساب الإداري والتسويقي | C59: تسويقي | D59: MAN00017 | E59: 14/5/2025 | F59: شركة إتقان المكان المحدودة | G59: مسوق | H59: فاتورة عمولة تسويق وبيع 222 فيلا | I59: مستحق | J59: 14/5/2025 | K59: 14/5/2025 | L59: 1675000
A60: 58 | B60: حساب الإداري والتسويقي | C60: اداري | D60: MAN00019 | E60: 21/5/2025 | F60: شركة اتقان للاستشارات المهنية | G60: المحاسب القانوني | H60: فاتورة أتعاب الإشراف المحاسبي أبريل 2025 | I60: مستحق | J60: 21/5/2025 | K60: 21/5/2025 | L60: 11500
A61: 59 | B61: حساب الإداري والتسويقي | C61: تسويقي | D61: MAN00020 | E61: 21/5/2025 | F61: شركة إتقان المكان المحدودة | G61: مسوق | H61: فاتورة عمولة تسويق وبيع 222 فيلا | I61: مستحق | J61: 21/5/2025 | K61: 21/5/2025 | L61: 4608184.5
A62: 60 | B62: حساب الإداري والتسويقي | C62: اداري | D62: MAN00022 | E62: 45722 | F62: شركة نبيل عباس للاستشارات الهندسية | G62: الاستشاري الهندسي | H62: رواتب الكادر الهندسي لشهر مايو 2025 | I62: مستحق | J62: 45722 | K62: 45722 | L62: 174223.15
A63: 61 | B63: حساب الإداري والتسويقي | C63: تسويقي | D63: MAN00021 | E63: 45722 | F63: شركة إتقان المكان المحدودة | G63: مسوق | H63: فاتورة عمولة تسويق وبيع 62 فيلا | I63: مستحق | J63: 45722 | K63: 45722 | L63: 2300000
A64: 62 | B64: حساب الإداري والتسويقي | C64: اداري | D64: MAN00023 | E64: 17/6/2025 | F64: شركة اتقان للاستشارات المهنية | G64: المحاسب القانوني | H64: فاتورة أتعاب الإشراف المحاسبي مايو 2025 | I64: مستحق | J64: 17/6/2025 | K64: 18/6/2025 | L64: 11500
A65: 63 | B65: حساب الإداري والتسويقي | C65: اداري | D65: MAN0024 | E65: 45723 | F65: شركة نبيل عباس للاستشارات الهندسية | G65: الاستشاري الهندسي | H65: أتعاب شهرية للاستشاري الهندسي | I65: مستحق | J65: 45723 | K65: 45815 | L65: 186622.13
A66: 64 | B66: حساب الإداري والتسويقي | C66: اداري | D66: MAN0025 | E66: 17/07/2025 | F66: شركة اتقان للاستشارات المهنية | G66: المحاسب القانوني | H66: أتعاب المراقب المالي | I66: مستحق | J66: 17/07/2025 | K66: 20/07/2025 | L66: 11500
...

Sheet Sheet1
A6: تقرير الربع | D6: بند وثائق الصرف | F6: صفة المستفيد | H6: نوع حساب الضمان
A7: Q1 | D7: انشائي | F7: مقاول | H7: حساب الانشاءات | J7: التكلفة المتبقية | K7: 20% من التكلفة الانشائية المتبقية | L7: حجز مبلغ الحفظ | O7: البنك | R7: حالة الوثيقة | T7: حساب الحفظ من الايداعات | U7: حساب الحفظ من التكلفة الانشائية
A8: Q2 | D8: اداري | F8: مورد | H8: حساب الإداري والتسويقي | J8: ='(1) البيانات الاساسية'!D9-'(3) العمليات المالية'!B9 -> -40197231 | K8: =J8*20% -> -8039446.2 | L8: ='(4) وحدات المشروع'!F51*4% -> 10183458 | O8: مصرف الانماء | R8: مقدم | T8: ='(3) العمليات المالية'!D9*4% -> 11465199 | U8: =('(1) البيانات الاساسية'!D9*5%) -> 9057885.4
A9: Q3 | D9: تسويقي | F9: ممول | H9: حساب الحفظ | O9: البنك الأهلي السعودي | R9: مستحق
A10: Q4 | D10: الحفظ (حسن التنفيذ) | F10: مشتري | O10: البنك السعودي الأول
D11: أخرى | F11: مسوق | O11: البنك السعودي الفرنسي
F12: الاستشاري الهندسي | O12: البنك العربي الوطني
F13: المحاسب القانوني | O13: بنك الامارات دبي الوطني
F14: أخرى (يتم ذكر صفة المستفيد في بيان الصرف) | O14: بنك البلاد
O15: بنك الجزيرة
O16: بنك الخليج الدولي
O17: بنك الرياض
O18: بنك الكويت الوطني
O19: مصرف الراجحي

Sheet (3) العمليات المالية
A5: رصيد إغلاق الربع السابق | C5: 48987477
A7: العمليات المالية منذ البدء بالمشروع | F7: العمليات المالية خلال الفترة
A8: العمليات المدينة | B8: المبلغ | C8: العمليات الدائنة | D8: المبلغ2 | F8: العمليات المدينة | G8: المبلغ | H8: العمليات الدائنة | I8: المبلغ2
A9: تكاليف انشائية | B9: 2.2135494e+08 | C9: تحصيل من العملاء | D9: 2.8662998e+08 | F9: تكاليف انشائية | G9: 35864883 | H9: تحصيل من العملاء | I9: 32043511
A10: تكاليف انشائية (الدفعة المقدمة المتبقية) | B10: 0 | C10: تمويل بنكي | D10: 0 | F10: تكاليف انشائية (تسويات الدفعة المقدمة) | G10: 0 | H10: تمويل بنكي | I10: 0
A11: مصاريف ادارية وتسويقية | B11: 31715784 | C11: تمويل ذاتي | D11: 0 | F11: مصاريف ادارية وتسويقية | G11: 2506852 | H11: تمويل ذاتي | I11: 0
A12: ايداعات عملاء مستردة | B12: 0 | C12: تمويل الوزارة | F12: ايداعات عملاء مستردة | G12: 0 | H12: تمويل الوزارة | I12: 0
A13: عمولات بنكية | B13: 0 | C13: أخرى() | D13: 504747.8 | F13: عمولات بنكية | G13: 0 | H13: أخرى() | I13: 0
A14: أخرى (مع ذكر السبب) | B14: 504747.8 | C14: أخرى (حوالة خاطئة) | D14: 9100000 | F14: أخرى (مع ذكر السبب) | G14: 0 | H14: أخرى (مع ذكر السبب) | I14: 0
A15: اجمالي العمليات المدينة | B15: =SUM(B9:B14) -> 2.5357547e+08 | C15: اجمالي العمليات الدائنة | D15: =SUM(D9:D14) -> 2.9623472e+08 | F15: اجمالي العمليات المدينة | G15: =SUM(G9:G14) -> 38371735 | H15: اجمالي العمليات الدائنة | I15: =SUM(I9:I14) -> 32043511
A17: أرصدة حساب الضمان | F17: العمليات المالية من خارج حساب الضمان (إن وجدت)
A18: رصيد افتتاح الفترة | B18: =C5 -> 48987477 | C18: رصيد اغلاق الفترة | D18: =B18+I15-G15 -> 42659252 | F18: العمليات المدينة | G18: المبلغ | H18: العمليات الدائنة | I18: المبلغ2
F19: تكاليف انشائية | G19: 0 | H19: تحصيل من العملاء | I19: 0
B20: تفاصيل الدفعة المقدمة | F20: مصاريف ادارية وتسويقية | G20: 0 | H20: تمويل بنكي | I20: 0
B21: البيان | C21: المدين | F21: ايداعات عملاء مستردة | G21: 0 | H21: تمويل ذاتي | I21: 0
B22: الرصيد الافتتاحي للدفعة المقدمة | F22: عمولات بنكية | G22: 0 | H22: تمويل الوزارة | I22: 0
B23: ما تم إنجازه من الدفعة المقدمة (تراكمي) | C23: =C22-C24 -> 0 | F23: أخرى (مع ذكر السبب) | G23: 0 | H23: أخرى (مع ذكر السبب) | I23: 0
B24: المتبقي من الدفعة المقدمة | C24: =B10 -> 0 | F24: اجمالي العمليات المدينة | G24: =SUM(G19:G23) -> 0 | H24: اجمالي العمليات الدائنة | I24: =SUM(I19:I23) -> 0
A26: القيود المالية | F26: العمليات المالية المتوقعة للربع القادم من العام الحالي (يتم ادخال العمليات المالية المتوقعة للربع القادم)
A27: المصاريف الإدارية التسويقي - الغير انشائية : 20% | B27: المبلغ | C27: حساب الحفظ: 5% | D27: المبلغ | F27: العمليات المدينة | G27: المبلغ | H27: العمليات الدائنة | I27: المبلغ2
A28: النسبة المسموح بها للمصاريف الإدارية والتسويقية | B28: (20% من قيمة الوحدة المباعة والمحصل قيمتها) | C28: النسبة الواجب توفرها بحساب الضمان | D28: (4% من قيمة الوحدة المباعة والمحصل قيمتها) | F28: تكاليف انشائية | G28: 31897867 | H28: تحصيل من العملاء | I28: 0
A29: إجمالي قيمة الوحدات المباعة والمحصل قيمتها | B29: ='(4) وحدات المشروع'!F51 -> 2.5458645e+08 | C29: الحد الأدنى الواجب توفره في حساب الضمان | D29: =Sheet1!U8 -> 9057885.4 | F29: تكاليف انشائية تسويات (دفعة مقدمة) | G29: 0 | H29: تمويل بنكي | I29: 0
A30: الحد المسموح التصرف به للمصاريف الإدارية والتسويقية | B30: =B29*20% -> 50917291 | C30: الحد المسموح التصرف به من حساب الضمان | D30: =Sheet1!T8-'(3) العمليات المالية'!D29 -> 2407313.6 | F30: مصاريف ادارية وتسويقية | G30: 0 | H30: تمويل ذاتي | I30: 0
A31: إجمالي المنصرف من الإدارية والتسويقية | B31: =B11 -> 31715784 | F31: ايداعات عملاء مستردة | G31: 0 | H31: تمويل الوزارة | I31: 0
A32: المبلغ المتبقي | B32: =B30-B31 -> 19201506 | F32: عمولات بنكية | G32: 0 | H32: أخرى (مع ذكر السبب) | I32: 0
F33: أخرى (مع ذكر السبب) | G33: 0 | H33: - | I33: 0
F34: اجمالي العمليات المدينة | G34: =SUM(G28:G33) -> 31897867 | H34: اجمالي العمليات الدائنة | I34: =SUM(I28:I33) -> 0

Sheet (4) وحدات المشروع
A1: البنود | B1: بيان نوع الوحدات | C1: عدد | D1: نسبة | E1: قيمة الوحدات | F1: قيمة المحصل من الوحدات المباعة | G1: المتبقي
A2: إجمالي وحدات المشروع | B2: شقق | C2: ='(1) البيانات الاساسية'!C20 -> 0 | D2: =C2/$C$17 -> 0 | E2: ='(1) البيانات الاساسية'!D20 -> 0 | F2: =F36 -> 0 | G2: =E2-F2 -> 0
B3: فلل | C3: ='(1) البيانات الاساسية'!C21 -> 455 | D3: =C3/$C$17 -> 1 | E3: ='(1) البيانات الاساسية'!D21 -> 3.1610032e+08 | F3: =F37 -> 2.5458645e+08 | G3: =E3-F3 -> 61513863
B4: دوبلكس | C4: ='(1) البيانات الاساسية'!C22 -> 0 | D4: =C4/$C$17 -> 0 | E4: ='(1) البيانات الاساسية'!D22 -> 0 | F4: =F38 -> 0 | G4: =E4-F4 -> 0
B5: أراضي سكنية | C5: ='(1) البيانات الاساسية'!C23 -> 0 | D5: =C5/$C$17 -> 0 | E5: ='(1) البيانات الاساسية'!D23 -> 0 | F5: =F39 -> 0 | G5: =E5-F5 -> 0
B6: أراضي تجارية | C6: ='(1) البيانات الاساسية'!C24 -> 0 | D6: =C6/$C$17 -> 0 | E6: ='(1) البيانات الاساسية'!D24 -> 0 | F6: =F40 -> 0 | G6: =E6-F6 -> 0
B7: أراضي صناعية | C7: ='(1) البيانات الاساسية'!C25 -> 0 | D7: =C7/$C$17 -> 0 | E7: ='(1) البيانات الاساسية'!D25 -> 0 | F7: =F41 -> 0 | G7: =E7-F7 -> 0
B8: أراضي زراعية | C8: ='(1) البيانات الاساسية'!C26 -> 0 | D8: =C8/$C$17 -> 0 | E8: ='(1) البيانات الاساسية'!D26 -> 0 | F8: =F42 -> 0 | G8: =E8-F8 -> 0
B9: أراضي سياحية | C9: ='(1) البيانات الاساسية'!C27 -> 0 | D9: =C9/$C$17 -> 0 | E9: ='(1) البيانات الاساسية'!D27 -> 0 | F9: =F43 -> 0 | G9: =E9-F9 -> 0
B10: أدوار | C10: ='(1) البيانات الاساسية'!C28 -> 0 | D10: =C10/$C$17 -> 0 | E10: ='(1) البيانات الاساسية'!D28 -> 0 | F10: =F44 -> 0 | G10: =E10-F10 -> 0
B11: مكاتب تجارية | C11: ='(1) البيانات الاساسية'!C29 -> 0 | D11: =C11/$C$17 -> 0 | E11: ='(1) البيانات الاساسية'!D29 -> 0 | F11: =F45 -> 0 | G11: =E11-F11 -> 0
B12: تاون هاوس | C12: ='(1) البيانات الاساسية'!C30 -> 0 | D12: =C12/$C$17 -> 0 | E12: ='(1) البيانات الاساسية'!D30 -> 0 | F12: =F46 -> 0 | G12: =E12-F12 -> 0
B13: مكاتب تجارية | C13: ='(1) البيانات الاساسية'!C31 -> 0 | D13: =C13/$C$17 -> 0 | E13: ='(1) البيانات الاساسية'!D31 -> 0 | F13: =F47 -> 0 | G13: =E13-F13 -> 0
B14: غرف فندقية | C14: ='(1) البيانات الاساسية'!C32 -> 0 | D14: =C14/$C$17 -> 0 | E14: ='(1) البيانات الاساسية'!D32 -> 0 | F14: =F48 -> 0 | G14: =E14-F14 -> 0
... B16: بنت هاوس | C16: ='(1) البيانات الاساسية'!C34 -> 0 | D16: =C16/$C$17 -> 0 | E16: ='(1) البيانات الاساسية'!D34 -> 0 | F16: =F50 -> 0 | G16: =E16-F16 -> 0
A17: الإجمالي | C17: =SUM(C2:C16) -> 455 | D17: =SUBTOTAL(109,D2:D16) -> 1 | E17: =SUM(E2:E16) -> 3.1610032e+08 | F17: =SUM(F2:F16) -> 2.5458645e+08 | G17: =SUM(G2:G16) -> 61513863
A18: اجمالي الوحدات المباعة خلال الفترة | B18: بيان نوع الوحدات | C18: عدد | D18: نسبة | E18: قيمة الوحدات | F18: قيمة المحصل من الوحدات المباعة | G18: المتبقي
B19: شقق | D19: =Table1921[[#This Row],[عدد]]/$C$34 -> #DIV/0! | G19: =E19-F19 -> 0
B20: فلل | D20: =Table1921[[#This Row],[عدد]]/$C$34 -> #DIV/0! | G20: =E20-F20 -> 0
B21: دوبلكس | D21: =Table1921[[#This Row],[عدد]]/$C$34 -> #DIV/0! | G21: =E21-F21 -> 0
B22: أراضي سكنية | D22: =Table1921[[#This Row],[عدد]]/$C$34 -> #DIV/0! | G22: =E22-F22 -> 0
B23: أراضي تجارية | D23: =Table1921[[#This Row],[عدد]]/$C$34 -> #DIV/0! | G23: =E23-F23 -> 0
B24: أراضي صناعية | D24: =Table1921[[#This Row],[عدد]]/$C$34 -> #DIV/0! | G24: =E24-F24 -> 0
B25: أراضي زراعية | D25: =Table1921[[#This Row],[عدد]]/$C$34 -> #DIV/0! | G25: =E25-F25 -> 0
B26: أراضي سياحية | D26: =Table1921[[#This Row],[عدد]]/$C$34 -> #DIV/0! | G26: =E26-F26 -> 0
B27: أدوار | D27: =Table1921[[#This Row],[عدد]]/$C$34 -> #DIV/0! | G27: =E27-F27 -> 0
B28: مكاتب تجارية | D28: =Table1921[[#This Row],[عدد]]/$C$34 -> #DIV/0! | G28: =E28-F28 -> 0
B29: تاون هاوس | D29: =Table1921[[#This Row],[عدد]]/$C$34 -> #DIV/0! | G29: =E29-F29 -> 0
B30: مكاتب تجارية | D30: =Table1921[[#This Row],[عدد]]/$C$34 -> #DIV/0! | G30: =E30-F30 -> 0
... B33: بنت هاوس | D33: =Table1921[[#This Row],[عدد]]/$C$34 -> #DIV/0! | G33: =E33-F33 -> 0
A34: الإجمالي | C34: =SUM(C19:C33) -> 0 | D34: =SUBTOTAL(109,D19:D33) -> #DIV/0! | E34: =SUBTOTAL(109,E19:E33) -> 0 | F34: =SUBTOTAL(109,F19:F33) -> 0 | G34: =SUBTOTAL(109,G19:G33) -> 0
A35: اجمالي الوحدات المباعة منذ بداية المشروع | B35: بيان نوع الوحدات | C35: عدد | D35: نسبة | E35: قيمة الوحدات | F35: قيمة المحصل من الوحدات المباعة | G35: المتبقي
B36: شقق | D36: =Table192122[[#This Row],[عدد]]/$C$51 -> 0 | G36: =E36-F36 -> 0
B37: فلل | C37: 455 | D37: =Table192122[[#This Row],[عدد]]/$C$51 -> 1 | E37: 3.1610032e+08 | F37: 2.5458645e+08 | G37: =E37-F37 -> 61513863
B38: دوبلكس | D38: =Table192122[[#This Row],[عدد]]/$C$51 -> 0 | G38: =E38-F38 -> 0
B39: أراضي سكنية | D39: =Table192122[[#This Row],[عدد]]/$C$51 -> 0 | G39: =E39-F39 -> 0
B40: أراضي تجارية | D40: =Table192122[[#This Row],[عدد]]/$C$51 -> 0 | G40: =E40-F40 -> 0
B41: أراضي صناعية | D41: =Table192122[[#This Row],[عدد]]/$C$51 -> 0 | G41: =E41-F41 -> 0
B42: أراضي زراعية | D42: =Table192122[[#This Row],[عدد]]/$C$51 -> 0 | G42: =E42-F42 -> 0
B43: أراضي سياحية | D43: =Table192122[[#This Row],[عدد]]/$C$51 -> 0 | G43: =E43-F43 -> 0
...

Sheet (5) تحليل البيانات المالية
A1: بيانات المشروع
A2: رقم الترخيص | B2: ='(1) البيانات الاساسية'!B7 -> أ/208
A3: اسم المشروع | B3: ='(1) البيانات الاساسية'!B8 -> ايال الاصالة
A4: اسم المطور | B4: ='(1) البيانات الاساسية'!B9 -> شركة محمد الحبيب العقارية
A5: المنطقة | B5: الرياض
A6: المدينة | B6: الرياض
A7: الحي | B7: الرياض
A8: الاستشاري الهندسي | B8: شركة نبيل محمد علي عباس للاستشارات الهندسية
A9: المحاسب القانوني | B9: ='(1) البيانات الاساسية'!B10 -> شركة إتقان للاستشارات المهنية
A10: آمين الحساب | B10: ='(1) البيانات الاساسية'!B11 -> بنك الرياض
A11: تاريخ بداية المشروع | B11: 45403
A12: تاريخ نهاية المشروع
A13: فرق الأيام | B13: =B12-TODAY() -> -46215
A15: مبلغ الفائض (الأرباح تقديري)
A16: الفائض بعد حجز 20% من التكلفة الانشائية المتبقية لاستكمال المشروع | B16: {=(Table10[[#All],[Column4]]-Sheet1!J8-Sheet1!K8)} -> 90895929
A17: الفائض بعد حجز 5% الحفظ | B17: =B16-Sheet1!L8 -> 80712471
A18: صافي الفائض المتاح | B18: =B17 -> 80712471
A19: عدد مرات سحب الفائض
A20: اجمالي قيمة سحوبات الفائض
A22: تحليل المعطيات التقديرية والفعلية
A23: البيان | B23: المقدر (دراسة الجدوى) | C23: الفعلي | D23: الفرق | E23: %
A24: اجمالي قيمة وحدات المشروع | B24: ='(1) البيانات الاساسية'!D8 -> 3.1610032e+08 | C24: ='(4) وحدات المشروع'!E51 -> 3.1610032e+08 | D24: =B24-C24 -> 0 | E24: =C24/B24 -> 1
A25: التكاليف الانشائية | B25: ='(1) البيانات الاساسية'!D9 -> 181157708 | C25: ='(3) العمليات المالية'!B9 -> 2.2135494e+08 | D25: =B25-C25 -> -40197231 | E25: =C25/B25 -> 1.2218908
A26: التكاليف الإدارية و التسويقية | B26: ='(1) البيانات الاساسية'!D10 -> 40849315 | C26: ='(3) العمليات المالية'!B11 -> 31715784 | D26: =B26-C26 -> 9133530.6 | E26: =C26/B26 -> 0.77640921

Sheet (6) النتائج والملاحظات
A1: نتائج ومرئيات
A2: 1 | B2: المبيعات
A7: 2 | B7: المصروفات
A12: 3 | B12: التحصيل / التمويل
A17: 4 | B17: المخاطرالحالية المتوقعة على المشروع
A23: 5 | B23: المخاطر المستقبلية المتوقعة على المشروع
A29: ملاحظات أخرى
A30: 1
A31: 2
A32: 3
A33: 4
A34: 5
A35: 6

Sheet قائمة المركز المالي (7)
F9: كما في 30 يونيو 2026
B10: الموجودات | F10: (بالريال السعودي)
B11: الموجودات المتداولة
B12: نقد وما في حكمه | F12: {=Table10[[#All],[Column4]]} -> 42659252 | I12: رصيد اغلاق الفترة
B13: اجمالي الموجودات المتداولة | F13: =SUM(F12) -> 42659252
B14: الموجودات غير المتداولة
B15: تكاليف عقود | F15: =Table7[[#This Row],[المبلغ]] -> 2.5357547e+08 | I15: اجمالي العمليات المدينة
B16: اجمالي الموجودات غير المتداولة | F16: =SUM(F15) -> 2.5357547e+08
B17: اجمالي الموجودات | F17: =+F16+F13 -> 2.9623472e+08
B20: المطلوبات
B21: المطلوبات المتداولة
B22: المبالغ المقدمة من المشترين | F22: ='(3) العمليات المالية'!D9 -> 2.8662998e+08 | I22: اجمالي تحصيل من العملاء
B23: أرصدة دائنة أخرى | F23: ='(3) العمليات المالية'!D13+'(3) العمليات المالية'!D14 -> 9604747.8 | I23: أخرى (حوالة خاطئة) دائنه
B24: اجمالي المطلوبات | F24: =SUM(F22:F23) -> 2.9623472e+08
F25: =F17-F24 -> 0
