Workbook

Sheet (1) البيانات الاساسية
A1: بيانات معد التقرير
A2: الاسم | C2: تاريخ التقرير
A3: رقم الجوال | C3: تقرير الربع
A4: البريد الإلكتروني
A6: البيانات الأساسية للمشروع
A7: رقم ترخيص المشروع | C7: سعر الارض
A8: اسم المشروع | C8: إجمالي قيمة وحدات المشروع | D8: =+D35 -> 0
A9: اسم المطور | C9: اجمالي التكاليف الانشائية التقديرية
A10: اسم مكتب المحاسب القانوني | C10: إجمالي التكاليف الإدارية التسويقية التقديرية
A11: آمين الحساب (البنك) | C11: اجمالي التكاليف التقديرية | D11: =+D10+D9 -> 0
A12: رقم حساب الضمان (ايبان) | C12: نسبة هامش الربح المتوقع | D12: =+(D8-D7-D11)/D8 -> #DIV/0!
A13: اسم المقاول | C13: قيمة عقد المقاول
A14: اسم المقاول 2 | C14: قيمة عقد المقاول 2
A15: اسم المقاول 3 | C15: قيمة عقد المقاول 3
A16: اسم المقاول 4 | C16: قيمة عقد المقاول 4
A18: وحدات المشروع
A19: نوع الوحدات | C19: العدد | D19: اجمالي قيمة الوحدات
A20: شقق
A21: فلل
A22: دوبلكس
A23: أراضي سكنية
A24: أراضي تجارية
A25: أراضي صناعية
A26: أراضي زراعية
A27: أراضي سياحية
A28: أدوار
A29: مكاتب تجارية
A30: تاون هاوس
A31: مكاتب تجارية
... A34: بنت هاوس
A35: الإجمالي | C35: =SUM(C20:C34) -> 0 | D35: =SUM(D20:D34) -> 0

Sheet (2) وثائق الصرف
A1: وثائق الصرف
A2: # | B2: نوع حساب الضمان | C2: البند | D2: رقم وثيقة الصرف | E2: تاريخ الوثيقة | F2: اسم المستفيد | G2: صفة المستفيد | H2: بيان الصرف | I2: حالة الوثيقة | J2: تاريخ اعتماد الوثيقة | K2: تاريخ الدفع | L2: المبلغ
A3: 1
A4: 2
A5: 3
A6: 4
A7: 5
A8: 6
A9: 7
A10: 8
A11: 9
A12: 10
A13: 11
A14: 12
... A16: 14
A17: الإجمالي | L17: =SUBTOTAL(109,L3:L16) -> 0

Sheet Sheet1
A6: تقرير الربع | B6: ارقام الرخص | D6: بند وثائق الصرف | F6: صفة المستفيد | H6: نوع حساب الضمان
A7: Q1 | B7: 3 | D7: انشائي | F7: مقاول | H7: حساب الانشاءات | J7: التكلفة المتبقية | K7: 20% من التكلفة الانشائية المتبقية | L7: حجز مبلغ الحفظ | O7: البنك | R7: حالة الوثيقة | T7: حساب الحفظ من الايداعات | U7: حساب الحفظ من التكلفة الانشائية
A8: Q2 | B8: 4 | D8: اداري | F8: مورد | H8: حساب الإداري والتسويقي | J8: ='[1](1) البيانات الاساسية'!D9-'[1](3) العمليات المالية'!B9 -> 50000 | K8: =J8*20% -> 10000 | L8: ='[1](4) وحدات المشروع'!F51*4% -> 5000 | O8: مصرف الانماء | R8: مقدم | T8: ='[1](3) العمليات المالية'!D9*4% -> 0 | U8: =('[1](1) البيانات الاساسية'!D9*5%) -> 5000
A9: Q3 | B9: 5 | D9: تسويقي | F9: ممول | H9: حساب الحفظ | O9: البنك الأهلي السعودي | R9: مستحق
A10: Q4 | B10: 7 | D10: الحفظ (حسن التنفيذ) | F10: مشتري | O10: البنك السعودي الأول
B11: 8 | D11: أخرى | F11: مسوق | O11: البنك السعودي الفرنسي
B12: 9 | F12: الاستشاري الهندسي | O12: البنك العربي الوطني
B13: 10 | F13: المحاسب القانوني | O13: بنك الامارات دبي الوطني
B14: 11 | F14: أخرى (يتم ذكر صفة المستفيد في بيان الصرف) | O14: بنك البلاد
B15: 12 | O15: بنك الجزيرة
B16: 13 | O16: بنك الخليج الدولي
B17: 17 | O17: بنك الرياض
B18: 14 | O18: بنك الكويت الوطني
B19: 18 | O19: مصرف الراجحي
B20: 20
B21: 23
B22: 24
B23: 25
B24: 26
B25: 27
B26: 28
B27: 29
B28: 19
B29: 30
B30: 31
B31: 32
... B58: 56
B59: أ/5
B60: 57
B61: 58
B62: 59
B63: 60
B64: 61
B65: 62
B66: أ/3
B67: أ/1
B68: 63
B69: أ/2
B70: 64
B71: أ/36
...

Sheet (3) العمليات المالية
A5: رصيد إغلاق الربع السابق | C5: 48987477
A7: العمليات المالية منذ البدء بالمشروع | F7: العمليات المالية خلال الفترة
A8: العمليات المدينة | B8: المبلغ | C8: العمليات الدائنة | D8: المبلغ2 | F8: العمليات المدينة | G8: المبلغ | H8: العمليات الدائنة | I8: المبلغ2
A9: تكاليف انشائية | B9: 2.2135494e+08 | C9: تحصيل من العملاء | D9: 2.8662998e+08 | F9: تكاليف انشائية | G9: 35864883 | H9: تحصيل من العملاء | I9: 32043511
A10: تكاليف انشائية (الدفعة المقدمة المتبقية) | B10: 0 | C10: تمويل بنكي | D10: 0 | F10: تكاليف انشائية (تسويات الدفعة المقدمة) | G10: 0 | H10: تمويل بنكي | I10: 0
A11: مصاريف ادارية وتسويقية | B11: 31715784 | C11: تمويل ذاتي | D11: 0 | F11: مصاريف ادارية وتسويقية | G11: 2506852 | H11: تمويل ذاتي | I11: 0
A12: ايداعات عملاء مستردة | B12: 0 | C12: تمويل الوزارة | D12: 0 | F12: ايداعات عملاء مستردة | G12: 0 | H12: تمويل الوزارة | I12: 0
A13: عمولات بنكية | B13: 0 | C13: أخرى (مع ذكر السبب) | D13: 504747.8 | F13: عمولات بنكية | G13: 0 | H13: أخرى (مع ذكر السبب) | I13: 0
A14: أخرى (مع ذكر السبب) | B14: 504747.8 | C14: أخرى 1 (مع ذكر السبب) | D14: 9100000 | F14: أخرى (مع ذكر السبب) | G14: 0 | H14: أخرى 1 (مع ذكر السبب) | I14: 0
A15: اجمالي العمليات المدينة | B15: =SUBTOTAL(109,B9:B14) -> 2.5357547e+08 | C15: اجمالي العمليات الدائنة | D15: =SUBTOTAL(109,D9:D14) -> 2.9623472e+08 | F15: اجمالي العمليات المدينة | G15: =SUBTOTAL(109,G9:G14) -> 38371735 | H15: اجمالي العمليات الدائنة | I15: =SUBTOTAL(109,I9:I14) -> 32043511
A17: أرصدة حساب الضمان | F17: العمليات المالية من خارج حساب الضمان (إن وجدت)
A18: رصيد افتتاح الفترة | B18: =+C5 -> 48987477 | C18: رصيد اغلاق الفترة | D18: {=+Table10[[#All],[Column2]]+I15-G15} -> 42659252 | F18: العمليات المدينة | G18: المبلغ | H18: العمليات الدائنة | I18: المبلغ2
F19: تكاليف انشائية | G19: =SUBTOTAL(109,G14:G18) -> 0 | H19: تحصيل من العملاء | I19: =SUBTOTAL(109,I14:I18) -> 0
B20: تفاصيل الدفعة المقدمة | F20: مصاريف ادارية وتسويقية | G20: =SUBTOTAL(109,G15:G19) -> 0 | H20: تمويل بنكي | I20: =SUBTOTAL(109,I15:I19) -> 0
B21: البيان | C21: المدين | F21: ايداعات عملاء مستردة | G21: =SUBTOTAL(109,G16:G20) -> 0 | H21: تمويل ذاتي | I21: =SUBTOTAL(109,I16:I20) -> 0
B22: الرصيد الافتتاحي للدفعة المقدمة | F22: عمولات بنكية | G22: =SUBTOTAL(109,G17:G21) -> 0 | H22: تمويل الوزارة | I22: =SUBTOTAL(109,I17:I21) -> 0
B23: ما تم إنجازه من الدفعة المقدمة (تراكمي) | C23: =-B10 -> 0 | F23: أخرى (مع ذكر السبب) | G23: =SUBTOTAL(109,G18:G22) -> 0 | H23: أخرى (مع ذكر السبب) | I23: =SUBTOTAL(109,I18:I22) -> 0
B24: المتبقي من الدفعة المقدمة | C24: =+C22+C23 -> 0 | F24: اجمالي العمليات المدينة | G24: =SUBTOTAL(109,G19:G23) -> 0 | H24: اجمالي العمليات الدائنة | I24: =SUBTOTAL(109,I19:I23) -> 0
A26: القيود المالية | F26: العمليات المالية المتوقعة للربع القادم من العام الحالي (يتم ادخال العمليات المالية المتوقعة للربع القادم)
A27: المصاريف الإدارية التسويقي - الغير انشائية : 20% | B27: المبلغ | C27: حساب الحفظ: 5% | D27: المبلغ | F27: العمليات المدينة | G27: المبلغ | H27: العمليات الدائنة | I27: المبلغ2
A28: النسبة المسموح بها للمصاريف الإدارية والتسويقية | B28: (20% من قيمة الوحدة المباعة والمحصل قيمتها) | C28: النسبة الواجب توفرها بحساب الضمان | D28: (4% من قيمة الوحدة المباعة والمحصل قيمتها) | F28: تكاليف انشائية | G28: =SUBTOTAL(109,G22:G27) -> 0 | H28: تحصيل من العملاء | I28: =SUBTOTAL(109,I23:I27) -> 0
A29: إجمالي قيمة الوحدات المباعة والمحصل قيمتها | B29: =+'(4) وحدات المشروع'!F51 -> 2.5458645e+08 | C29: الحد الأدنى الواجب توفره في حساب الضمان | D29: =+'(1) البيانات الاساسية'!D9*0.05 -> 0 | F29: تكاليف انشائية تسويات (دفعة مقدمة) | G29: =SUBTOTAL(109,G23:G28) -> 0 | H29: تمويل بنكي | I29: =SUBTOTAL(109,I24:I28) -> 0
A30: الحد المسموح التصرف به للمصاريف الإدارية والتسويقية | B30: =+B29*0.2 -> 50917291 | C30: الحد المسموح التصرف به من حساب الضمان | D30: =+D9*0.04-D29 -> 11465199 | F30: مصاريف ادارية وتسويقية | G30: =SUBTOTAL(109,G24:G29) -> 0 | H30: تمويل ذاتي | I30: =SUBTOTAL(109,I25:I29) -> 0
A31: إجمالي المنصرف من الإدارية والتسويقية | B31: =+B11 -> 31715784 | F31: ايداعات عملاء مستردة | G31: =SUBTOTAL(109,G25:G30) -> 0 | H31: تمويل الوزارة | I31: =SUBTOTAL(109,I26:I30) -> 0
A32: المبلغ المتبقي | B32: =+B30-B31 -> 19201506 | F32: عمولات بنكية | G32: =SUBTOTAL(109,G26:G31) -> 0 | H32: أخرى (مع ذكر السبب) | I32: =SUBTOTAL(109,I27:I31) -> 0
F33: أخرى (مع ذكر السبب) | G33: =SUBTOTAL(109,G27:G32) -> 0 | H33: - | I33: =SUBTOTAL(109,I28:I32) -> 0
F34: اجمالي العمليات المدينة | G34: =SUBTOTAL(109,G28:G33) -> 0 | H34: اجمالي العمليات الدائنة | I34: =SUBTOTAL(109,I28:I33) -> 0

Sheet (4) وحدات المشروع
A1: البنود | B1: بيان نوع الوحدات | C1: عدد | D1: نسبة | E1: قيمة الوحدات | F1: قيمة المحصل من الوحدات المباعة | G1: المتبقي
A2: إجمالي وحدات المشروع | B2: شقق | C2: =+'(1) البيانات الاساسية'!C20 -> 0 | D2: =+Table19[[#This Row],[عدد]]/$C$17 -> #DIV/0! | E2: =+'(1) البيانات الاساسية'!D20 -> 0 | F2: =+F36 -> 0 | G2: 0
B3: فلل | C3: =+'(1) البيانات الاساسية'!C21 -> 0 | D3: =+Table19[[#This Row],[عدد]]/$C$17 -> #DIV/0! | E3: =+'(1) البيانات الاساسية'!D21 -> 0 | F3: 0 | G3: 0
B4: دوبلكس | C4: =+'(1) البيانات الاساسية'!C22 -> 0 | D4: =+Table19[[#This Row],[عدد]]/$C$17 -> #DIV/0! | E4: =+'(1) البيانات الاساسية'!D22 -> 0 | F4: 0 | G4: 0
B5: أراضي سكنية | C5: =+'(1) البيانات الاساسية'!C23 -> 0 | D5: =+Table19[[#This Row],[عدد]]/$C$17 -> #DIV/0! | E5: =+'(1) البيانات الاساسية'!D23 -> 0 | F5: 0 | G5: 0
B6: أراضي تجارية | C6: =+'(1) البيانات الاساسية'!C24 -> 0 | D6: =+Table19[[#This Row],[عدد]]/$C$17 -> #DIV/0! | E6: =+'(1) البيانات الاساسية'!D24 -> 0 | F6: 0 | G6: 0
B7: أراضي صناعية | C7: =+'(1) البيانات الاساسية'!C25 -> 0 | D7: =+Table19[[#This Row],[عدد]]/$C$17 -> #DIV/0! | E7: =+'(1) البيانات الاساسية'!D25 -> 0 | F7: 0 | G7: 0
B8: أراضي زراعية | C8: =+'(1) البيانات الاساسية'!C26 -> 0 | D8: =+Table19[[#This Row],[عدد]]/$C$17 -> #DIV/0! | E8: =+'(1) البيانات الاساسية'!D26 -> 0 | F8: 0 | G8: 0
B9: أراضي سياحية | C9: =+'(1) البيانات الاساسية'!C27 -> 0 | D9: =+Table19[[#This Row],[عدد]]/$C$17 -> #DIV/0! | E9: =+'(1) البيانات الاساسية'!D27 -> 0 | F9: 0 | G9: 0
B10: أدوار | C10: =+'(1) البيانات الاساسية'!C28 -> 0 | D10: =+Table19[[#This Row],[عدد]]/$C$17 -> #DIV/0! | E10: =+'(1) البيانات الاساسية'!D28 -> 0 | F10: 0 | G10: 0
B11: مكاتب تجارية | C11: =+'(1) البيانات الاساسية'!C29 -> 0 | D11: =+Table19[[#This Row],[عدد]]/$C$17 -> #DIV/0! | E11: =+'(1) البيانات الاساسية'!D29 -> 0 | F11: 0 | G11: 0
B12: تاون هاوس | C12: =+'(1) البيانات الاساسية'!C30 -> 0 | D12: =+Table19[[#This Row],[عدد]]/$C$17 -> #DIV/0! | E12: =+'(1) البيانات الاساسية'!D30 -> 0 | F12: 0 | G12: 0
B13: مكاتب تجارية | C13: =+'(1) البيانات الاساسية'!C31 -> 0 | D13: =+Table19[[#This Row],[عدد]]/$C$17 -> #DIV/0! | E13: =+'(1) البيانات الاساسية'!D31 -> 0 | F13: 0 | G13: 0
B14: غرف فندقية | C14: =+'(1) البيانات الاساسية'!C32 -> 0 | D14: =+Table19[[#This Row],[عدد]]/$C$17 -> #DIV/0! | E14: =+'(1) البيانات الاساسية'!D32 -> 0 | F14: 0 | G14: 0
... B16: بنت هاوس | C16: =+'(1) البيانات الاساسية'!C34 -> 0 | D16: =+Table19[[#This Row],[عدد]]/$C$17 -> #DIV/0! | E16: =+'(1) البيانات الاساسية'!D34 -> 0 | F16: 0 | G16: 0
A17: الإجمالي | C17: =SUBTOTAL(109,C2:C16) -> 0 | D17: =SUBTOTAL(109,D2:D16) -> #DIV/0! | E17: =SUBTOTAL(109,E2:E16) -> 0 | F17: =SUBTOTAL(109,F2:F16) -> 0 | G17: =SUBTOTAL(109,G2:G16) -> 0
A18: اجمالي الوحدات المباعة خلال الفترة | B18: بيان نوع الوحدات | C18: عدد | D18: نسبة | E18: قيمة الوحدات | F18: قيمة المحصل من الوحدات المباعة | G18: المتبقي
B19: شقق | D19: =+Table1921[[#This Row],[عدد]]/$C$34 -> #DIV/0! | G19: 0
B20: فلل | D20: =+Table1921[[#This Row],[عدد]]/$C$34 -> #DIV/0! | G20: 0
B21: دوبلكس | D21: =+Table1921[[#This Row],[عدد]]/$C$34 -> #DIV/0! | G21: 0
B22: أراضي سكنية | D22: =+Table1921[[#This Row],[عدد]]/$C$34 -> #DIV/0! | G22: 0
B23: أراضي تجارية | D23: =+Table1921[[#This Row],[عدد]]/$C$34 -> #DIV/0! | G23: 0
B24: أراضي صناعية | D24: =+Table1921[[#This Row],[عدد]]/$C$34 -> #DIV/0! | G24: 0
B25: أراضي زراعية | D25: =+Table1921[[#This Row],[عدد]]/$C$34 -> #DIV/0! | G25: 0
B26: أراضي سياحية | D26: =+Table1921[[#This Row],[عدد]]/$C$34 -> #DIV/0! | G26: 0
B27: أدوار | D27: =+Table1921[[#This Row],[عدد]]/$C$34 -> #DIV/0! | G27: 0
B28: مكاتب تجارية | D28: =+Table1921[[#This Row],[عدد]]/$C$34 -> #DIV/0! | G28: 0
B29: تاون هاوس | D29: =+Table1921[[#This Row],[عدد]]/$C$34 -> #DIV/0! | G29: 0
B30: مكاتب تجارية | D30: =+Table1921[[#This Row],[عدد]]/$C$34 -> #DIV/0! | G30: 0
... B33: بنت هاوس | D33: =+Table1921[[#This Row],[عدد]]/$C$34 -> #DIV/0! | G33: 0
A34: الإجمالي | C34: =SUBTOTAL(109,C19:C33) -> 0 | D34: =SUBTOTAL(109,D19:D33) -> #DIV/0! | E34: =SUM(E19:E33) -> 0 | F34: =SUM(F19:F33) -> 0 | G34: =SUM(G19:G33) -> 0
A35: اجمالي الوحدات المباعة منذ بداية المشروع | B35: بيان نوع الوحدات | C35: عدد | D35: نسبة | E35: قيمة الوحدات | F35: قيمة المحصل من الوحدات المباعة | G35: المتبقي
B36: شقق | D36: =+Table192122[[#This Row],[عدد]]/$C$51 -> 0 | G36: 0
B37: فلل | C37: 455 | D37: =+Table192122[[#This Row],[عدد]]/$C$51 -> 1 | E37: 3.1610032e+08 | F37: 2.5458645e+08 | G37: 0
B38: دوبلكس | D38: =+Table192122[[#This Row],[عدد]]/$C$51 -> 0 | G38: 0
B39: أراضي سكنية | D39: =+Table192122[[#This Row],[عدد]]/$C$51 -> 0 | G39: 0
B40: أراضي تجارية | D40: =+Table192122[[#This Row],[عدد]]/$C$51 -> 0 | G40: 0
B41: أراضي صناعية | D41: =+Table192122[[#This Row],[عدد]]/$C$51 -> 0 | G41: 0
B42: أراضي زراعية | D42: =+Table192122[[#This Row],[عدد]]/$C$51 -> 0 | G42: 0
B43: أراضي سياحية | D43: =+Table192122[[#This Row],[عدد]]/$C$51 -> 0 | G43: 0
...

Sheet (5) تحليل البيانات المالية
A1: بيانات المشروع
A2: رقم الترخيص
A3: اسم المشروع
A4: اسم المطور
A5: المنطقة
A6: المدينة
A7: الحي
A8: الاستشاري الهندسي
A9: المحاسب القانوني
A10: آمين الحساب
A11: تاريخ بداية المشروع
A12: تاريخ نهاية المشروع
A13: فرق الأيام | B13: =+B12-TODAY() -> -46287
A15: مبلغ الفائض (الأرباح تقديري)
A16: الفائض بعد حجز 20% من التكلفة الانشائية المتبقية لاستكمال المشروع | B16: {=(-D25*1.2)+Table10[[#All],[Column4]]} -> 3.0828518e+08
A17: الفائض بعد حجز 5% الحفظ | B17: =+B16-B25*0.05 -> 3.0828518e+08
A18: صافي الفائض المتاح | B18: =+B17 -> 3.0828518e+08
A19: عدد مرات سحب الفائض
A20: اجمالي قيمة سحوبات الفائض
A22: تحليل المعطيات التقديرية والفعلية
A23: البيان | B23: المقدر (دراسة الجدوى) | C23: الفعلي | D23: الفرق | E23: %
A24: اجمالي قيمة وحدات المشروع | B24: =+'(1) البيانات الاساسية'!D8 -> 0 | C24: =+'(4) وحدات المشروع'!E51 -> 3.1610032e+08 | D24: =+B24-C24 -> -3.1610032e+08 | E24: =+C24/B24 -> #DIV/0!
A25: التكاليف الانشائية | B25: =+'(1) البيانات الاساسية'!D9 -> 0 | C25: =+'(3) العمليات المالية'!B9 -> 2.2135494e+08 | D25: =+B25-C25 -> -2.2135494e+08 | E25: =+C25/B25 -> #DIV/0!
A26: التكاليف الإدارية و التسويقية | B26: =+'(1) البيانات الاساسية'!D10 -> 0 | C26: =+'(3) العمليات المالية'!B11 -> 31715784 | D26: =+B26-C26 -> -31715784 | E26: =+C26/B26 -> #DIV/0!

Sheet (6) النتائج والملاحظات
A1: نتائج ومرئيات
A2: 1 | B2: المبيعات
A9: 2 | B9: المصروفات
A16: 3 | B16: التحصيل / التمويل
A22: 4 | B22: المخاطرالحالية المتوقعة على المشروع
A28: 5 | B28: المخاطر المستقبلية المتوقعة على المشروع
A34: ملاحظات أخرى
A35: 6

Sheet قائمة المركز المالي (7)
E9: كما في | F9: تاريخ التقرير
B10: الموجودات | F10: (بالريال السعودي)
B11: الموجودات المتداولة
B12: نقد وما في حكمه | F12: {=+Table10[[#All],[Column4]]} -> 42659252
B13: اجمالي الموجودات المتداولة | F13: =SUM(F12) -> 42659252
B14: الموجودات غير المتداولة
B15: تكاليف عقود | F15: =+'(3) العمليات المالية'!B9+'(3) العمليات المالية'!B10+'(3) العمليات المالية'!B11+'(3) العمليات المالية'!B13 -> 2.5307072e+08
B16: اجمالي الموجودات غير المتداولة | F16: =SUM(F15) -> 2.5307072e+08
B17: اجمالي الموجودات | F17: =+F16+F13 -> 2.9572998e+08
B20: المطلوبات
B21: المطلوبات المتداولة
B22: المبالغ المقدمة من المشترين | F22: =+'(3) العمليات المالية'!D9-'(3) العمليات المالية'!B12 -> 2.8662998e+08
B23: تمويل بنكي | F23: =+'(3) العمليات المالية'!D10 -> 0
B24: تمويل ذاتي | F24: =+'(3) العمليات المالية'!D11 -> 0
B25: تمويل الوزارة | F25: =+'(3) العمليات المالية'!D12 -> 0
B26: أرصدة دائنة أخرى | F26: =+'(3) العمليات المالية'!D13+'(3) العمليات المالية'!D14-'(3) العمليات المالية'!B14 -> 9100000
B27: اجمالي المطلوبات | F27: =SUM(F22:F26) -> 2.9572998e+08
F28: =F17-F27 -> 0
