Workbook

Sheet مقدمة
A1: #VALUE!
A10: النموذج الموحد لتقرير المحاسب القانوني للمشاريع العقارية على الخارطة

Sheet تعليمات هامة قبل البدء
A1: #VALUE!
B7: إرشادات وتعليمات هامة في تعبئة النموذج الموحد لتقرير المحاسب القانوني للمشاريع العقارية على الخارطة
B9: تـــعـــلـــيـــمـــات عـــامـــة:
B10: # المسؤول عن تعبئة ودقة البيانات والمعلومات وتسليم التقرير وفق النموذج الموحد هو مكتب المحاسب القانوني الخاص بالمشروع العقاري على الخارطة المرخص من قبل الهيئة العامة للعقار
B11: # تسمية الملف تتضمن اسم المشروع مع فترة التقرير. (مثال: مشروع الهيئة العامة للعقار- الربع الثالث 2026)
B12: # جميع الحقول إلزامية ويجب تعبئتها، ويتم استخدام "لا ينطبق أو 0" في حال كانت الخانة لا تنطبق على الطلب
B13: # المهلة النهائية لتسليم التقرير خلال مدة أقصاها (21 يوم فقط) من نهاية الربع. (مثال : المهلة النهائية لتسليم تقرير الربع الثالث 2026 تبدأ من 1 أكتوبر 2026، وتنتهي في 21 أكتوبر 2026)
B14: # في حال عدم تزويد المطور للمحاسب القانوني بالبيانات اللازمة لإعداد التقرير يجب الإفادة رسمياً من قبل المحاسب القانوني بذلك خلال مدة أقصاها (3) أيام عمل من نهاية الربع، ولن يُعتد بأي إفادة ترد بعد انقضاء هذه المدة
B15: # لن يتم استلام أي تقرير بعد المهلة الزمنية المحدة، ولايوجد تمديد أو استثناء، وسيتم الرفع بالمخالفة حسب الإجراءات النظامية دون إشعار مسبق
B16: # لن يتم استلام أي تقرير غير مستوفي كافة الحقول المطلوبة، وسيتم الرفع بالمخالفة حسب الإجراءات النظامية دون إشعار مسبق
B17: # يتم الاستناد على المخالفات وفقاً لنظام بيع وتأجير مشروعات عقارية على الخارطة، واللائحة التنفيذية لنظام بيع وتأجير مشروعات عقارية على الخارطة، وجدول مخالفات نظام بيع وتأجير مشروعات عقارية على الخارطة ولائحته التنفيذية والعقوبات المقررة لها
B18: # يتم تعبئة النموذج باللغة العربية في حال كان طبيعة الحقل (نص)، ويتم التعبئة باللغة الإنجليزية في حال طبيعة الحقل (رقم 12345)
B19: # توجد ملاحظة استرشادية على بعض الحقول
... B91: • يهدف هذا القسم في إرفاق قائمة المركز المالي للمشروع

Sheet (1) البيانات الاساسية
A1: بيانات معد التقرير
A2: الاسم | C2: تاريخ التقرير
A3: رقم الجوال | B3: 543007030 | C3: تقرير الربع
A4: البريد الإلكتروني
A6: البيانات الأساسية للمشروع
A7: رقم ترخيص المشروع | C7: سعر الارض | D7: ( حسب بداية المشروع)
A8: اسم المشروع | C8: إجمالي قيمة وحدات المشروع | D8: =D35 -> 0
A9: اسم المطور | C9: اجمالي التكاليف الانشائية التقديرية | D9: ( حسب بداية المشروع)
A10: اسم مكتب المحاسب القانوني | C10: إجمالي التكاليف الإدارية التسويقية التقديرية | D10: ( حسب بداية المشروع)
A11: آمين الحساب (البنك) | B11: مصرف الانماء | C11: اجمالي التكاليف التقديرية | D11: =D9+D10 -> #VALUE!
A12: رقم حساب الضمان (ايبان) | C12: نسبة هامش الربح المتوقع | D12: =(D8-(D9+D10+D7))/D8 -> #VALUE!
A13: اسم المقاول | C13: قيمة عقد المقاول
A14: اسم المقاول 2 | C14: قيمة عقد المقاول 2
A15: اسم المقاول 3 | C15: قيمة عقد المقاول 3
A16: اسم المقاول 4 | C16: قيمة عقد المقاول 4
A18: وحدات المشروع
A19: نوع الوحدات | C19: العدد | D19: اجمالي قيمة الوحدات
A20: شقق
A21: فلل
A22: دوبلكس
A23: أراضي سكنية
A24: أراضي تجارية
A25: أراضي صناعية
A26: أراضي زراعية
A27: أراضي سياحية
A28: أدوار
A29: مكاتب تجارية
A30: تاون هاوس
A31: مكاتب تجارية
... A34: بنت هاوس
A35: الإجمالي | C35: =SUM(C20:C34) -> 0 | D35: =SUM(D20:D34) -> 0

Sheet (2) وثائق الصرف
A1: وثائق الصرف
A2: # | B2: نوع حساب الضمان | C2: البند | D2: رقم وثيقة الصرف | E2: تاريخ الوثيقة | F2: اسم المستفيد | G2: صفة المستفيد | H2: بيان الصرف | I2: حالة الوثيقة | J2: تاريخ اعتماد الوثيقة | K2: تاريخ الدفع | L2: المبلغ
A3: 1 | F3: شركة الحديد للمقاولات | G3: أخرى (يتم ذكر صفة المستفيد في بيان الصرف) | H3: مستخلص رقم () لأعمال البناء | I3: مستحق
A4: 2 | F4: شركة سحا لتوريد | H4: دفعة مقدمة توريد مواد بناء | I4: مقدم
A5: 3 | F5: بنك الأهلي | H5: الغاء عقد وإعادة الدفعات للوحدة رقم .... | L5: 1000000
A6: 4 | F6: سعود | H6: الغاء عقد وإعادة دفعات
A7: 5 | F7: شركة الدعاية والاعلان | H7: الدفعة الأولى من عقد تسويق المشروع
A8: 6 | F8: شركة بداية للتمويل | H8: سداد مستحقات تمويل المشروع دفعة رقم 3
A9: 7 | F9: الشركة الوطنية للإسكان | H9: سداد مستحقات تمويل الحافز الوزاري
A10: 8 | F10: شركة التسويق العقاري | H10: سداد عمولات التسويق من بيع الوحدات
A11: 9 | F11: الاستشاري الهندسي | H11: سداد اتعاب مكتب الاستشاري الهندسي
A12: 10 | F12: المحاسب القانوني | H12: سداد اتعاب مكتب المحاسب القانوني
A13: 11
A14: 12
A15: 13
A16: 14
A17: الإجمالي | L17: =SUBTOTAL(109,L3:L16) -> 1000000

Sheet Sheet1
A6: تقرير الربع | B6: ارقام الرخص | D6: بند وثائق الصرف | F6: صفة المستفيد | H6: نوع حساب الضمان
A7: Q1 | B7: 3 | D7: انشائي | F7: مقاول | H7: حساب الانشاءات | J7: التكلفة المتبقية | K7: 20% من التكلفة الانشائية المتبقية | L7: حجز مبلغ الحفظ | O7: البنك | R7: حالة الوثيقة | T7: حساب الحفظ من الايداعات | U7: حساب الحفظ من التكلفة الانشائية
A8: Q2 | B8: 4 | D8: اداري | F8: مورد | H8: حساب الإداري والتسويقي | J8: ='(1) البيانات الاساسية'!D9-'(3) العمليات المالية'!B9 -> #VALUE! | K8: =J8*20% -> #VALUE! | L8: ='(4) وحدات المشروع'!F51*4% -> 0 | O8: مصرف الانماء | R8: مقدم | T8: ='(3) العمليات المالية'!D9*4% -> 0 | U8: =('(1) البيانات الاساسية'!D9*5%) -> #VALUE!
A9: Q3 | B9: 5 | D9: تسويقي | F9: ممول | H9: حساب الحفظ | O9: البنك الأهلي السعودي | R9: مستحق
A10: Q4 | B10: 7 | D10: الحفظ (حسن التنفيذ) | F10: مشتري | O10: البنك السعودي الأول
B11: 8 | D11: أخرى | F11: مسوق | O11: البنك السعودي الفرنسي
B12: 9 | F12: الاستشاري الهندسي | O12: البنك العربي الوطني
B13: 10 | F13: المحاسب القانوني | O13: بنك الامارات دبي الوطني
B14: 11 | F14: أخرى (يتم ذكر صفة المستفيد في بيان الصرف) | O14: بنك البلاد
B15: 12 | O15: بنك الجزيرة
B16: 13 | O16: بنك الخليج الدولي
B17: 17 | O17: بنك الرياض
B18: 14 | O18: بنك الكويت الوطني
B19: 18 | O19: مصرف الراجحي
B20: 20
B21: 23
B22: 24
B23: 25
B24: 26
B25: 27
B26: 28
B27: 29
B28: 19
B29: 30
B30: 31
B31: 32
... B58: 56
B59: أ/5
B60: 57
B61: 58
B62: 59
B63: 60
B64: 61
B65: 62
B66: أ/3
B67: أ/1
B68: 63
B69: أ/2
B70: 64
B71: أ/36
...

Sheet (3) العمليات المالية
A5: رصيد إغلاق الربع السابق
A7: العمليات المالية منذ البدء بالمشروع | F7: العمليات المالية خلال الفترة
A8: العمليات المدينة | B8: المبلغ | C8: العمليات الدائنة | D8: المبلغ2 | F8: العمليات المدينة | G8: المبلغ | H8: العمليات الدائنة | I8: المبلغ2
A9: تكاليف انشائية | C9: تحصيل من العملاء | F9: تكاليف انشائية | H9: تحصيل من العملاء
A10: تكاليف انشائية (الدفعة المقدمة المتبقية) | C10: تمويل بنكي | F10: تكاليف انشائية (تسويات الدفعة المقدمة) | H10: تمويل بنكي
A11: مصاريف ادارية وتسويقية | C11: تمويل ذاتي | F11: مصاريف ادارية وتسويقية | H11: تمويل ذاتي
A12: ايداعات عملاء مستردة | C12: تمويل الوزارة | F12: ايداعات عملاء مستردة | H12: تمويل الوزارة
A13: عمولات بنكية | C13: أخرى (مع ذكر السبب) | F13: عمولات بنكية | H13: أخرى (مع ذكر السبب)
A14: أخرى (مع ذكر السبب) | C14: أخرى 1 (مع ذكر السبب) | F14: أخرى (مع ذكر السبب) | H14: أخرى 1 (مع ذكر السبب)
A15: اجمالي العمليات المدينة | B15: =SUM(B9:B14) -> 0 | C15: اجمالي العمليات الدائنة | D15: =SUM(D9:D14) -> 0 | F15: اجمالي العمليات المدينة | G15: =SUM(G9:G14) -> 0 | H15: اجمالي العمليات الدائنة | I15: =SUM(I9:I14) -> 0
A17: أرصدة حساب الضمان | F17: العمليات المالية من خارج حساب الضمان (إن وجدت)
A18: رصيد افتتاح الفترة | B18: =C5 -> 0 | C18: رصيد اغلاق الفترة | D18: =B18+I15-G15 -> 0 | F18: العمليات المدينة | G18: المبلغ | H18: العمليات الدائنة | I18: المبلغ2
F19: تكاليف انشائية | H19: تحصيل من العملاء
B20: تفاصيل الدفعة المقدمة | F20: مصاريف ادارية وتسويقية | H20: تمويل بنكي
B21: البيان | C21: المدين | F21: ايداعات عملاء مستردة | H21: تمويل ذاتي
B22: الرصيد الافتتاحي للدفعة المقدمة | F22: عمولات بنكية | H22: تمويل الوزارة
B23: ما تم إنجازه من الدفعة المقدمة (تراكمي) | C23: =C22-C24 -> 0 | F23: أخرى (مع ذكر السبب) | H23: أخرى (مع ذكر السبب)
B24: المتبقي من الدفعة المقدمة | C24: =B10 -> 0 | F24: اجمالي العمليات المدينة | G24: =SUM(G19:G23) -> 0 | H24: اجمالي العمليات الدائنة | I24: =SUM(I19:I23) -> 0
A26: القيود المالية | F26: العمليات المالية المتوقعة للربع القادم من العام الحالي (يتم ادخال العمليات المالية المتوقعة للربع القادم)
A27: المصاريف الإدارية التسويقي - الغير انشائية : 20% | B27: المبلغ | C27: حساب الحفظ: 5% | D27: المبلغ | F27: العمليات المدينة | G27: المبلغ | H27: العمليات الدائنة | I27: المبلغ2
A28: النسبة المسموح بها للمصاريف الإدارية والتسويقية | B28: (20% من قيمة الوحدة المباعة والمحصل قيمتها) | C28: النسبة الواجب توفرها بحساب الضمان | D28: (4% من قيمة الوحدة المباعة والمحصل قيمتها) | F28: تكاليف انشائية | H28: تحصيل من العملاء
A29: إجمالي قيمة الوحدات المباعة والمحصل قيمتها | B29: ='(4) وحدات المشروع'!F51 -> 0 | C29: الحد الأدنى الواجب توفره في حساب الضمان | D29: =Sheet1!U8 -> #VALUE! | F29: تكاليف انشائية تسويات (دفعة مقدمة) | H29: تمويل بنكي
A30: الحد المسموح التصرف به للمصاريف الإدارية والتسويقية | B30: =B29*20% -> 0 | C30: الحد المسموح التصرف به من حساب الضمان | D30: =Sheet1!T8-'(3) العمليات المالية'!D29 -> #VALUE! | F30: مصاريف ادارية وتسويقية | H30: تمويل ذاتي
A31: إجمالي المنصرف من الإدارية والتسويقية | B31: =B11 -> 0 | F31: ايداعات عملاء مستردة | H31: تمويل الوزارة
A32: المبلغ المتبقي | B32: =B30-B31 -> 0 | F32: عمولات بنكية | H32: أخرى (مع ذكر السبب)
F33: أخرى (مع ذكر السبب) | H33: - | I33: -
F34: اجمالي العمليات المدينة | G34: =SUM(G28:G33) -> 0 | H34: اجمالي العمليات الدائنة | I34: =SUM(I28:I33) -> 0

Sheet (4) وحدات المشروع
A1: البنود | B1: بيان نوع الوحدات | C1: عدد | D1: نسبة | E1: قيمة الوحدات | F1: قيمة المحصل من الوحدات المباعة | G1: المتبقي
A2: إجمالي وحدات المشروع | B2: شقق | C2: ='(1) البيانات الاساسية'!C20 -> 0 | D2: =C2/$C$17 -> #DIV/0! | E2: ='(1) البيانات الاساسية'!D20 -> 0 | F2: =F36 -> 0 | G2: =E2-F2 -> 0
B3: فلل | C3: ='(1) البيانات الاساسية'!C21 -> 0 | D3: =C3/$C$17 -> #DIV/0! | E3: ='(1) البيانات الاساسية'!D21 -> 0 | F3: =F37 -> 0 | G3: =E3-F3 -> 0
B4: دوبلكس | C4: ='(1) البيانات الاساسية'!C22 -> 0 | D4: =C4/$C$17 -> #DIV/0! | E4: ='(1) البيانات الاساسية'!D22 -> 0 | F4: =F38 -> 0 | G4: =E4-F4 -> 0
B5: أراضي سكنية | C5: ='(1) البيانات الاساسية'!C23 -> 0 | D5: =C5/$C$17 -> #DIV/0! | E5: ='(1) البيانات الاساسية'!D23 -> 0 | F5: =F39 -> 0 | G5: =E5-F5 -> 0
B6: أراضي تجارية | C6: ='(1) البيانات الاساسية'!C24 -> 0 | D6: =C6/$C$17 -> #DIV/0! | E6: ='(1) البيانات الاساسية'!D24 -> 0 | F6: =F40 -> 0 | G6: =E6-F6 -> 0
B7: أراضي صناعية | C7: ='(1) البيانات الاساسية'!C25 -> 0 | D7: =C7/$C$17 -> #DIV/0! | E7: ='(1) البيانات الاساسية'!D25 -> 0 | F7: =F41 -> 0 | G7: =E7-F7 -> 0
B8: أراضي زراعية | C8: ='(1) البيانات الاساسية'!C26 -> 0 | D8: =C8/$C$17 -> #DIV/0! | E8: ='(1) البيانات الاساسية'!D26 -> 0 | F8: =F42 -> 0 | G8: =E8-F8 -> 0
B9: أراضي سياحية | C9: ='(1) البيانات الاساسية'!C27 -> 0 | D9: =C9/$C$17 -> #DIV/0! | E9: ='(1) البيانات الاساسية'!D27 -> 0 | F9: =F43 -> 0 | G9: =E9-F9 -> 0
B10: أدوار | C10: ='(1) البيانات الاساسية'!C28 -> 0 | D10: =C10/$C$17 -> #DIV/0! | E10: ='(1) البيانات الاساسية'!D28 -> 0 | F10: =F44 -> 0 | G10: =E10-F10 -> 0
B11: مكاتب تجارية | C11: ='(1) البيانات الاساسية'!C29 -> 0 | D11: =C11/$C$17 -> #DIV/0! | E11: ='(1) البيانات الاساسية'!D29 -> 0 | F11: =F45 -> 0 | G11: =E11-F11 -> 0
B12: تاون هاوس | C12: ='(1) البيانات الاساسية'!C30 -> 0 | D12: =C12/$C$17 -> #DIV/0! | E12: ='(1) البيانات الاساسية'!D30 -> 0 | F12: =F46 -> 0 | G12: =E12-F12 -> 0
B13: مكاتب تجارية | C13: ='(1) البيانات الاساسية'!C31 -> 0 | D13: =C13/$C$17 -> #DIV/0! | E13: ='(1) البيانات الاساسية'!D31 -> 0 | F13: =F47 -> 0 | G13: =E13-F13 -> 0
B14: غرف فندقية | C14: ='(1) البيانات الاساسية'!C32 -> 0 | D14: =C14/$C$17 -> #DIV/0! | E14: ='(1) البيانات الاساسية'!D32 -> 0 | F14: =F48 -> 0 | G14: =E14-F14 -> 0
... B16: بنت هاوس | C16: ='(1) البيانات الاساسية'!C34 -> 0 | D16: =C16/$C$17 -> #DIV/0! | E16: ='(1) البيانات الاساسية'!D34 -> 0 | F16: =F50 -> 0 | G16: =E16-F16 -> 0
A17: الإجمالي | C17: =SUM(C2:C16) -> 0 | D17: =SUBTOTAL(109,D2:D16) -> #DIV/0! | E17: =SUM(E2:E16) -> 0 | F17: =SUM(F2:F16) -> 0 | G17: =SUM(G2:G16) -> 0
A18: اجمالي الوحدات المباعة خلال الفترة | B18: بيان نوع الوحدات | C18: عدد | D18: نسبة | E18: قيمة الوحدات | F18: قيمة المحصل من الوحدات المباعة | G18: المتبقي
B19: شقق | D19: =Table1921[[#This Row],[عدد]]/$C$34 -> #DIV/0! | G19: =E19-F19 -> 0
B20: فلل | D20: =Table1921[[#This Row],[عدد]]/$C$34 -> #DIV/0! | G20: =E20-F20 -> 0
B21: دوبلكس | D21: =Table1921[[#This Row],[عدد]]/$C$34 -> #DIV/0! | G21: =E21-F21 -> 0
B22: أراضي سكنية | D22: =Table1921[[#This Row],[عدد]]/$C$34 -> #DIV/0! | G22: =E22-F22 -> 0
B23: أراضي تجارية | D23: =Table1921[[#This Row],[عدد]]/$C$34 -> #DIV/0! | G23: =E23-F23 -> 0
B24: أراضي صناعية | D24: =Table1921[[#This Row],[عدد]]/$C$34 -> #DIV/0! | G24: =E24-F24 -> 0
B25: أراضي زراعية | D25: =Table1921[[#This Row],[عدد]]/$C$34 -> #DIV/0! | G25: =E25-F25 -> 0
B26: أراضي سياحية | D26: =Table1921[[#This Row],[عدد]]/$C$34 -> #DIV/0! | G26: =E26-F26 -> 0
B27: أدوار | D27: =Table1921[[#This Row],[عدد]]/$C$34 -> #DIV/0! | G27: =E27-F27 -> 0
B28: مكاتب تجارية | D28: =Table1921[[#This Row],[عدد]]/$C$34 -> #DIV/0! | G28: =E28-F28 -> 0
B29: تاون هاوس | D29: =Table1921[[#This Row],[عدد]]/$C$34 -> #DIV/0! | G29: =E29-F29 -> 0
B30: مكاتب تجارية | D30: =Table1921[[#This Row],[عدد]]/$C$34 -> #DIV/0! | G30: =E30-F30 -> 0
... B33: بنت هاوس | D33: =Table1921[[#This Row],[عدد]]/$C$34 -> #DIV/0! | G33: =E33-F33 -> 0
A34: الإجمالي | C34: =SUM(C19:C33) -> 0 | D34: =SUBTOTAL(109,D19:D33) -> #DIV/0! | E34: =SUBTOTAL(109,E19:E33) -> 0 | F34: =SUBTOTAL(109,F19:F33) -> 0 | G34: =SUBTOTAL(109,G19:G33) -> 0
A35: اجمالي الوحدات المباعة منذ بداية المشروع | B35: بيان نوع الوحدات | C35: عدد | D35: نسبة | E35: قيمة الوحدات | F35: قيمة المحصل من الوحدات المباعة | G35: المتبقي
B36: شقق | D36: =Table192122[[#This Row],[عدد]]/$C$51 -> #DIV/0! | G36: =E36-F36 -> 0
B37: فلل | D37: =Table192122[[#This Row],[عدد]]/$C$51 -> #DIV/0! | G37: =E37-F37 -> 0
B38: دوبلكس | D38: =Table192122[[#This Row],[عدد]]/$C$51 -> #DIV/0! | G38: =E38-F38 -> 0
B39: أراضي سكنية | D39: =Table192122[[#This Row],[عدد]]/$C$51 -> #DIV/0! | G39: =E39-F39 -> 0
B40: أراضي تجارية | D40: =Table192122[[#This Row],[عدد]]/$C$51 -> #DIV/0! | G40: =E40-F40 -> 0
B41: أراضي صناعية | D41: =Table192122[[#This Row],[عدد]]/$C$51 -> #DIV/0! | G41: =E41-F41 -> 0
B42: أراضي زراعية | D42: =Table192122[[#This Row],[عدد]]/$C$51 -> #DIV/0! | G42: =E42-F42 -> 0
B43: أراضي سياحية | D43: =Table192122[[#This Row],[عدد]]/$C$51 -> #DIV/0! | G43: =E43-F43 -> 0
...

Sheet (5) تحليل البيانات المالية
A1: بيانات المشروع
A2: رقم الترخيص | B2: ='(1) البيانات الاساسية'!B7 -> 0
A3: اسم المشروع | B3: ='(1) البيانات الاساسية'!B8 -> 0
A4: اسم المطور | B4: ='(1) البيانات الاساسية'!B9 -> 0
A5: المنطقة
A6: المدينة
A7: الحي
A8: الاستشاري الهندسي
A9: المحاسب القانوني | B9: ='(1) البيانات الاساسية'!B10 -> 0
A10: آمين الحساب | B10: ='(1) البيانات الاساسية'!B11 -> مصرف الانماء
A11: تاريخ بداية المشروع | B11: 45658
A12: تاريخ نهاية المشروع | B12: 46347
A13: فرق الأيام | B13: =B12-TODAY() -> 67
A15: مبلغ الفائض (الأرباح تقديري)
A16: الفائض بعد حجز 20% من التكلفة الانشائية المتبقية لاستكمال المشروع | B16: {=(Table10[[#All],[Column4]]-Sheet1!J8-Sheet1!K8)} -> #VALUE!
A17: الفائض بعد حجز 5% الحفظ | B17: =B16-Sheet1!L8 -> #VALUE!
A18: صافي الفائض المتاح | B18: =B17 -> #VALUE!
A19: عدد مرات سحب الفائض
A20: اجمالي قيمة سحوبات الفائض
A22: تحليل المعطيات التقديرية والفعلية
A23: البيان | B23: المقدر (دراسة الجدوى) | C23: الفعلي | D23: الفرق | E23: %
A24: اجمالي قيمة وحدات المشروع | B24: ='(1) البيانات الاساسية'!D8 -> 0 | C24: ='(4) وحدات المشروع'!E51 -> 0 | D24: =B24-C24 -> 0 | E24: =C24/B24 -> #DIV/0!
A25: التكاليف الانشائية | B25: ='(1) البيانات الاساسية'!D9 -> ( حسب بداية المشروع) | C25: ='(3) العمليات المالية'!B9 -> 0 | D25: =B25-C25 -> #VALUE! | E25: =C25/B25 -> #VALUE!
A26: التكاليف الإدارية و التسويقية | B26: ='(1) البيانات الاساسية'!D10 -> ( حسب بداية المشروع) | C26: ='(3) العمليات المالية'!B11 -> 0 | D26: =B26-C26 -> #VALUE! | E26: =C26/B26 -> #VALUE!

Sheet (6) النتائج والملاحظات
A1: نتائج ومرئيات
A2: 1 | B2: المبيعات
A9: 2 | B9: المصروفات
A16: 3 | B16: التحصيل / التمويل
A22: 4 | B22: المخاطرالحالية المتوقعة على المشروع
A28: 5 | B28: المخاطر المستقبلية المتوقعة على المشروع
A34: ملاحظات أخرى
A35: 6

Sheet قائمة المركز المالي (7)
